2020-01-09 07:13:01,266 opmysql.py[line:119] ERROR (1146, "Table 'you.cases_interface' doesn't exist")
Traceback (most recent call last):
  File "E:\python_workspace\autotest_interface\common\opmysql.py", line 102, in select_all
    rows_affect = self.cur.execute(condition)
  File "D:\Program Files (x86)\Python36-32\lib\site-packages\pymysql\cursors.py", line 170, in execute
    result = self._query(query)
  File "D:\Program Files (x86)\Python36-32\lib\site-packages\pymysql\cursors.py", line 328, in _query
    conn.query(q)
  File "D:\Program Files (x86)\Python36-32\lib\site-packages\pymysql\connections.py", line 517, in query
    self._affected_rows = self._read_query_result(unbuffered=unbuffered)
  File "D:\Program Files (x86)\Python36-32\lib\site-packages\pymysql\connections.py", line 732, in _read_query_result
    result.read()
  File "D:\Program Files (x86)\Python36-32\lib\site-packages\pymysql\connections.py", line 1075, in read
    first_packet = self.connection._read_packet()
  File "D:\Program Files (x86)\Python36-32\lib\site-packages\pymysql\connections.py", line 684, in _read_packet
    packet.check_error()
  File "D:\Program Files (x86)\Python36-32\lib\site-packages\pymysql\protocol.py", line 220, in check_error
    err.raise_mysql_exception(self._data)
  File "D:\Program Files (x86)\Python36-32\lib\site-packages\pymysql\err.py", line 109, in raise_mysql_exception
    raise errorclass(errno, errval)
pymysql.err.ProgrammingError: (1146, "Table 'you.cases_interface' doesn't exist")
2020-01-09 07:13:01,388 opmysql.py[line:119] ERROR (1146, "Table 'you.cases_interface' doesn't exist")
Traceback (most recent call last):
  File "E:\python_workspace\autotest_interface\common\opmysql.py", line 102, in select_all
    rows_affect = self.cur.execute(condition)
  File "D:\Program Files (x86)\Python36-32\lib\site-packages\pymysql\cursors.py", line 170, in execute
    result = self._query(query)
  File "D:\Program Files (x86)\Python36-32\lib\site-packages\pymysql\cursors.py", line 328, in _query
    conn.query(q)
  File "D:\Program Files (x86)\Python36-32\lib\site-packages\pymysql\connections.py", line 517, in query
    self._affected_rows = self._read_query_result(unbuffered=unbuffered)
  File "D:\Program Files (x86)\Python36-32\lib\site-packages\pymysql\connections.py", line 732, in _read_query_result
    result.read()
  File "D:\Program Files (x86)\Python36-32\lib\site-packages\pymysql\connections.py", line 1075, in read
    first_packet = self.connection._read_packet()
  File "D:\Program Files (x86)\Python36-32\lib\site-packages\pymysql\connections.py", line 684, in _read_packet
    packet.check_error()
  File "D:\Program Files (x86)\Python36-32\lib\site-packages\pymysql\protocol.py", line 220, in check_error
    err.raise_mysql_exception(self._data)
  File "D:\Program Files (x86)\Python36-32\lib\site-packages\pymysql\err.py", line 109, in raise_mysql_exception
    raise errorclass(errno, errval)
pymysql.err.ProgrammingError: (1146, "Table 'you.cases_interface' doesn't exist")
